<?xml version="1.0" encoding="utf-8" ?>
<!-- =================================================================================== -->
<!-- |    This document was autogenerated by xacro from /home/guo/catkin_ws/src/robot_description/urdf/arm.xacro | -->
<!-- |    EDITING THIS FILE BY HAND IS NOT RECOMMENDED                                 | -->
<!-- =================================================================================== -->
<robot name="zeal_robot">
    <link name="base_link">
        <visual>
            <origin rpy="0 0 0" xyz=" 0 0 0" />
            <geometry>
                <cylinder length="0.0" radius="0.0" />
            </geometry>
            <material name="Yellow" />
        </visual>
    </link>
    <link name="arm_left_link_1_s">
        <visual>
            <origin rpy="0 0 0" xyz="0 0 0" />
            <geometry>
                <mesh filename="package://robot_description/meshes/sda10f/visual/motoman_axis_s.stl" />
            </geometry>
            <material name="blue">
                <color rgba="0.8 0.8 0.8 1" />
            </material>
        </visual>
        <collision>
            <origin rpy="0 0 0" xyz="0 0 0" />
            <geometry>
                <mesh filename="package://robot_description/meshes/sda10f/collision/motoman_axis_s.stl" />
            </geometry>
            <material name="yellow">
                <color rgba="1 1 0 1" />
            </material>
        </collision>
        
<inertial>
            <mass value="10.0" />
            <origin rpy="0 0 0" xyz="-0.000265 -0.022912 -0.263484" />
            <inertia ixx="0.112042" ixy="-9.49E-06" ixz="5.84E-06" iyy="0.026163" iyz="-0.022776" izz="0.110175" />
        </inertial>

    </link>
    <gazebo reference="arm_left_link_1_s">
        <material>Gazebo/Blue</material>
        <gravity>true</gravity>
    </gazebo>
    <link name="arm_left_link_2_l">
        <visual>
            <origin rpy="0 0 0" xyz="0 0 0" />
            <geometry>
                <mesh filename="package://robot_description/meshes/sda10f/visual/motoman_axis_l.stl" />
            </geometry>
            <material name="silver" />
        </visual>
        <collision>
            <origin rpy="0 0 0" xyz="0 0 0" />
            <geometry>
                <mesh filename="package://robot_description/meshes/sda10f/collision/motoman_axis_l.stl" />
            </geometry>
            <material name="yellow" />
        </collision>
        
<inertial>
            <mass value="8.0" />
            <origin rpy="0 0 0" xyz="0.0 0.079945 -0.009835" />
            <inertia ixx="0.112042" ixy="-9.49E-06" ixz="5.84E-06" iyy="0.026163" iyz="-0.022776" izz="0.110175" />
        </inertial>

    </link>
    <gazebo reference="arm_left_link_2_l">
        <material>Gazebo/White</material>
        <gravity>true</gravity>
    </gazebo>
    <link name="arm_left_link_3_e">
        <visual>
            <origin rpy="0 0 0" xyz="0 0 0" />
            <geometry>
                <mesh filename="package://robot_description/meshes/sda10f/visual/motoman_axis_e.stl" />
            </geometry>
            <material name="blue" />
        </visual>
        <collision>
            <origin rpy="0 0 0" xyz="0 0 0" />
            <geometry>
                <mesh filename="package://robot_description/meshes/sda10f/collision/motoman_axis_e.stl" />
            </geometry>
            <material name="yellow" />
        </collision>
        
<inertial>
            <mass value="7.5" />
            <origin rpy="0 0 0" xyz="0.0 0.018717 -0.119158" />
            <inertia ixx="0.156550" ixy="-8.43E-06" ixz="4.35E-05" iyy="0.152788" iyz="-0.021001" izz="0.017946" />
        </inertial>

    </link>
    <gazebo reference="arm_left_link_3_e">
        <material>Gazebo/Blue</material>
        <gravity>true</gravity>
    </gazebo>
    <link name="arm_left_link_4_u">
        <visual>
            <origin rpy="0 0 0" xyz="0 0 0" />
            <geometry>
                <mesh filename="package://robot_description/meshes/sda10f/visual/motoman_axis_u.stl" />
            </geometry>
            <material name="silver" />
        </visual>
        <collision>
            <origin rpy="0 0 0" xyz="0 0 0" />
            <geometry>
                <mesh filename="package://robot_description/meshes/sda10f/collision/motoman_axis_u.stl" />
            </geometry>
            <material name="yellow" />
        </collision>
        
<inertial>
            <mass value="6.0" />
            <origin rpy="0 0 0" xyz="0.0 0.093003 -0.006433" />
            <inertia ixx="0.092098" ixy="-4.04E-05" ixz="-3.81E-06" iyy="0.010300" iyz="0.004406" izz="0.091086" />
        </inertial>

    </link>
    <gazebo reference="arm_left_link_4_u">
        <material>Gazebo/White</material>
        <gravity>true</gravity>
    </gazebo>
    <link name="arm_left_link_5_r">
        <visual>
            <origin rpy="0 0 0" xyz="0 0 0" />
            <geometry>
                <mesh filename="package://robot_description/meshes/sda10f/visual/motoman_axis_r.stl" />
            </geometry>
            <material name="blue" />
        </visual>
        <collision>
            <origin rpy="0 0 0" xyz="0 0 0" />
            <geometry>
                <mesh filename="package://robot_description/meshes/sda10f/collision/motoman_axis_r.stl" />
            </geometry>
            <material name="yellow" />
        </collision>
        
<inertial>
            <mass value="5.5" />
            <origin rpy="0 0 0" xyz="0.0 -0.0134 -0.133989" />
            <inertia ixx="0.134067" ixy="5.74E-06" ixz="3.19E-05" iyy="0.132025" iyz="0.013502" izz="0.008969" />
        </inertial>

    </link>
    <gazebo reference="arm_left_link_5_r">
        <material>Gazebo/Blue</material>
        <gravity>true</gravity>
    </gazebo>
    <link name="arm_left_link_6_b">
        <visual>
            <origin rpy="0 0 0" xyz="0 0 0" />
            <geometry>
                <mesh filename="package://robot_description/meshes/sda10f/visual/motoman_axis_b.stl" />
            </geometry>
            <material name="silver" />
        </visual>
        <collision>
            <origin rpy="0 0 0" xyz="0 0 0" />
            <geometry>
                <mesh filename="package://robot_description/meshes/sda10f/collision/motoman_axis_b.stl" />
            </geometry>
            <material name="yellow" />
        </collision>
        
<inertial>
            <mass value="3.5" />
            <origin rpy="0 0 0" xyz="0.0 0.05919 0.001493" />
            <inertia ixx="0.024033" ixy="-1.78E-05" ixz="3.03E-06" iyy="0.005402" iyz="-0.002585" izz="0.023675" />
        </inertial>

    </link>
    <gazebo reference="arm_left_link_6_b">
        <material>Gazebo/White</material>
        <gravity>true</gravity>
    </gazebo>
    <link name="arm_left_link_7_t">
        <visual>
            <geometry>
                <mesh filename="package://robot_description/meshes/sda10f/visual/motoman_axis_t.stl" />
            </geometry>
            <material name="blue" />
        </visual>
        <collision>
            <geometry>
                <mesh filename="package://robot_description/meshes/sda10f/collision/motoman_axis_t.stl" />
            </geometry>
            <material name="yellow" />
        </collision>
        
<inertial>
            <mass value="1.5" />
            <origin rpy="0 0 0" xyz="0.0 0.00015 -0.02467" />
            <inertia ixx="0.002083" ixy="0.0" ixz="0.0" iyy="0.002100" iyz="9.8E-07" izz="0.001926" />
        </inertial>

    </link>
    <gazebo reference="arm_left_link_7_t">
        <material>Gazebo/Blue</material>
        <gravity>true</gravity>
    </gazebo>
    <link name="arm_left_link_tool0" />
    <joint name="arm_left_joint_1_s" type="revolute">
        <parent link="base_link" />
        <child link="arm_left_link_1_s" />
        <origin rpy="0.0 3.14 3.14" xyz="0.0 0 0.0" />
        <axis xyz="0 0 -1" />
        <limit effort="5.0" lower="-3.13" upper="3.13" velocity="2.95" />
        <dynamics damping="0.7" friction="0.7" />
    </joint>
    <joint name="arm_left_joint_2_l" type="revolute">
        <parent link="arm_left_link_1_s" />
        <child link="arm_left_link_2_l" />
        <origin rpy="-1.57 0 0" xyz="0 0.0577 -0.2255" />
        <axis xyz="0 0 -1" />
        <limit effort="5.0" lower="-1.90" upper="1.90" velocity="2.95" />
        <dynamics damping="0.7" friction="0.7" />
    </joint>
    <joint name="arm_left_joint_3_e" type="revolute">
        <parent link="arm_left_link_2_l" />
        <child link="arm_left_link_3_e" />
        <origin rpy="1.57 0 0" xyz="0 0.1690 -0.0454" />
        <axis xyz="0 0 -1" />
        <limit effort="5.0" lower="-2.95" upper="2.95" velocity="2.95" />
        <dynamics damping="0.7" friction="0.7" />
    </joint>
    <joint name="arm_left_joint_4_u" type="revolute">
        <parent link="arm_left_link_3_e" />
        <child link="arm_left_link_4_u" />
        <origin rpy="-1.57 0 0" xyz="0 -0.0085 -0.181" />
        <axis xyz="0 0 1" />
        <limit effort="5.0" lower="-2.36" upper="2.36" velocity="2.95" />
        <dynamics damping="0.7" friction="0.7" />
    </joint>
    <joint name="arm_left_joint_5_r" type="revolute">
        <parent link="arm_left_link_4_u" />
        <child link="arm_left_link_5_r" />
        <origin rpy="1.57 0 0" xyz="0 0.1936 0.0155" />
        <axis xyz="0 0 1" />
        <limit effort="5.0" lower="-3.13" upper="3.13" velocity="3.48" />
        <dynamics damping="0.7" friction="0.7" />
    </joint>
    <joint name="arm_left_joint_6_b" type="revolute">
        <parent link="arm_left_link_5_r" />
        <child link="arm_left_link_6_b" />
        <origin rpy="-1.57 0 0" xyz="0 0.0080 -0.155" />
        <axis xyz="0 0 1" />
        <limit effort="5.0" lower="-1.90" upper="1.90" velocity="3.48" />
        <dynamics damping="0.7" friction="0.7" />
    </joint>
    <joint name="arm_left_joint_7_t" type="revolute">
        <parent link="arm_left_link_6_b" />
        <child link="arm_left_link_7_t" />
        <origin rpy="1.57 0 0" xyz="0 0.168 -0.015" />
        <axis xyz="0 0 -1" />
        <limit effort="5.0" lower="-3.13" upper="3.13" velocity="6.97" />
        <dynamics damping="0.7" friction="0.7" />
    </joint>
    <joint name="arm_left_joint_tool0" type="fixed">
        <origin rpy="0 0 -3.13" xyz="0 0 0.0" />
        <parent link="arm_left_link_7_t" />
        <child link="arm_left_link_tool0" />
    </joint>
    <!-- transmission list -->
    
<transmission name="arm_left_tran_1_s">
        <type>transmission_interface/SimpleTransmission</type>
        <joint name="arm_left_joint_1_s">
            <hardwareInterface>hardware_interface/PositionJointInterface</hardwareInterface>
        </joint>
        <actuator name="arm_left_motor_1_s">
            <mechanicalReduction>1</mechanicalReduction>
        </actuator>
    </transmission>
    <transmission name="arm_left_tran_2_l">
        <type>transmission_interface/SimpleTransmission</type>
        <joint name="arm_left_joint_2_l">
            <hardwareInterface>hardware_interface/PositionJointInterface</hardwareInterface>
        </joint>
        <actuator name="arm_left_motor_2_l">
            <mechanicalReduction>1</mechanicalReduction>
        </actuator>
    </transmission>
    <transmission name="arm_left_tran_3_e">
        <type>transmission_interface/SimpleTransmission</type>
        <joint name="arm_left_joint_3_e">
            <hardwareInterface>hardware_interface/PositionJointInterface</hardwareInterface>
        </joint>
        <actuator name="arm_left_motor_3_e">
            <mechanicalReduction>1</mechanicalReduction>
        </actuator>
    </transmission>
    <transmission name="arm_left_tran_4_u">
        <type>transmission_interface/SimpleTransmission</type>
        <joint name="arm_left_joint_4_u">
            <hardwareInterface>hardware_interface/PositionJointInterface</hardwareInterface>
        </joint>
        <actuator name="arm_left_motor_4_u">
            <mechanicalReduction>1</mechanicalReduction>
        </actuator>
    </transmission>
    <transmission name="arm_left_tran_5_r">
        <type>transmission_interface/SimpleTransmission</type>
        <joint name="arm_left_joint_5_r">
            <hardwareInterface>hardware_interface/PositionJointInterface</hardwareInterface>
        </joint>
        <actuator name="arm_left_motor_5_r">
            <mechanicalReduction>1</mechanicalReduction>
        </actuator>
    </transmission>
    <transmission name="arm_left_tran_6_b">
        <type>transmission_interface/SimpleTransmission</type>
        <joint name="arm_left_joint_6_b">
            <hardwareInterface>hardware_interface/PositionJointInterface</hardwareInterface>
        </joint>
        <actuator name="arm_left_motor_6_b">
            <mechanicalReduction>1</mechanicalReduction>
        </actuator>
    </transmission>
    <transmission name="arm_left_tran_7_t">
        <type>transmission_interface/SimpleTransmission</type>
        <joint name="arm_left_joint_7_t">
            <hardwareInterface>hardware_interface/PositionJointInterface</hardwareInterface>
        </joint>
        <actuator name="arm_left_motor_7_t">
            <mechanicalReduction>1</mechanicalReduction>
        </actuator>
    </transmission>
    <!-- end of transmission list -->
    <!--ros_control-->
    <transmission name="trans_arm_left_joint_1_s">
        <type>transmission_interface/SimpleTransmission</type>
        <joint name="arm_left_joint_1_s">
            <hardwareInterface>hardware_interface/EffortJointInterface</hardwareInterface>
        </joint>
        <actuator name="arm_left_joint_1_s_motor">
            <hardwareInterface>hardware_interface/EffortJointInterface</hardwareInterface>
            <mechanicalReduction>1</mechanicalReduction>
        </actuator>
    </transmission>
    <transmission name="trans_arm_left_joint_2_l">
        <type>transmission_interface/SimpleTransmission</type>
        <joint name="arm_left_joint_2_l">
            <hardwareInterface>hardware_interface/EffortJointInterface</hardwareInterface>
        </joint>
        <actuator name="arm_left_joint_2_l_motor">
            <hardwareInterface>hardware_interface/EffortJointInterface</hardwareInterface>
            <mechanicalReduction>1</mechanicalReduction>
        </actuator>
    </transmission>
    <transmission name="trans_arm_left_joint_3_e">
        <type>transmission_interface/SimpleTransmission</type>
        <joint name="arm_left_joint_3_e">
            <hardwareInterface>hardware_interface/EffortJointInterface</hardwareInterface>
        </joint>
        <actuator name="arm_left_joint_3_e_motor">
            <hardwareInterface>hardware_interface/EffortJointInterface</hardwareInterface>
            <mechanicalReduction>1</mechanicalReduction>
        </actuator>
    </transmission>
    <transmission name="trans_arm_left_joint_4_u">
        <type>transmission_interface/SimpleTransmission</type>
        <joint name="arm_left_joint_4_u">
            <hardwareInterface>hardware_interface/EffortJointInterface</hardwareInterface>
        </joint>
        <actuator name="arm_left_joint_4_u_motor">
            <hardwareInterface>hardware_interface/EffortJointInterface</hardwareInterface>
            <mechanicalReduction>1</mechanicalReduction>
        </actuator>
    </transmission>
    <transmission name="trans_arm_left_joint_5_r">
        <type>transmission_interface/SimpleTransmission</type>
        <joint name="arm_left_joint_5_r">
            <hardwareInterface>hardware_interface/EffortJointInterface</hardwareInterface>
        </joint>
        <actuator name="arm_left_joint_5_r_motor">
            <hardwareInterface>hardware_interface/EffortJointInterface</hardwareInterface>
            <mechanicalReduction>1</mechanicalReduction>
        </actuator>
    </transmission>
    <transmission name="trans_arm_left_joint_6_b">
        <type>transmission_interface/SimpleTransmission</type>
        <joint name="arm_left_joint_6_b">
            <hardwareInterface>hardware_interface/EffortJointInterface</hardwareInterface>
        </joint>
        <actuator name="arm_left_joint_6_b_motor">
            <hardwareInterface>hardware_interface/EffortJointInterface</hardwareInterface>
            <mechanicalReduction>1</mechanicalReduction>
        </actuator>
    </transmission>
    <transmission name="trans_arm_left_joint_7_t">
        <type>transmission_interface/SimpleTransmission</type>
        <joint name="arm_left_joint_7_t">
            <hardwareInterface>hardware_interface/EffortJointInterface</hardwareInterface>
        </joint>
        <actuator name="arm_left_joint_7_t_motor">
            <hardwareInterface>hardware_interface/EffortJointInterface</hardwareInterface>
            <mechanicalReduction>1</mechanicalReduction>
        </actuator>
    </transmission>
    <gazebo>
        <plugin name="gazebo_ros_control" filename="libgazebo_ros_control.so">
            <robotNamespace>/</robotNamespace>
        </plugin>
    </gazebo>
</robot>