<?xml version="1.0" encoding="utf-8"?>
<!-- This URDF was automatically created by SolidWorks to URDF Exporter! Originally created by Stephen Brawner (brawner@gmail.com) 
     Commit Version: 1.6.0-1-g15f4949  Build Version: 1.6.7594.29634
     For more information, please see http://wiki.ros.org/sw_urdf_exporter -->
<robot
  name="hand_description">
  <!-- <mujoco>
    <compiler meshdir="./" balanceinertia="false" discardvisual="false"/>
  </mujoco> -->

  <link
    name="hand_base_link">
    <inertial>
      <origin
        xyz="-0.024622 -0.006074 -0.014249"
        rpy="0 0 0" />
      <mass
        value="1.07" />
      <inertia
        ixx="0.0020474"
        ixy="6.8483E-05"
        ixz="-6.1489E-05"
        iyy="0.0017405"
        iyz="-1.2361E-05"
        izz="0.00069716" />
    </inertial>
    <visual>
      <origin
        xyz="0 0 0"
        rpy="0 0 0" />
      <geometry>
        <mesh
          filename="package://base_link.STL" />
      </geometry>
      <material
        name="">
        <color
          rgba="0.79216 0.81961 0.93333 1" />
      </material>
    </visual>
    <collision>
      <origin
        xyz="0 0 0"
        rpy="0 0 0" />
      <geometry>
        <mesh
          filename="package://base_link.STL" />
      </geometry>
    </collision>
  </link>
  <link
    name="fi1-1">
    <inertial>
      <origin
        xyz="0 0 -0.006816"
        rpy="0 0 0" />
      <mass
        value="0.006" />
      <inertia
        ixx="2.93E-07"
        ixy="0"
        ixz="0"
        iyy="3.19E-07"
        iyz="0"
        izz="5.1E-08" />
    </inertial>
    <visual>
      <origin
        xyz="0 0 0"
        rpy="0 0 0" />
      <geometry>
        <mesh
          filename="package://fi1-1.STL" />
      </geometry>
      <material
        name="">
        <color
          rgba="0.7 0.8 0.9 1" />
      </material>
    </visual>
    <collision>
      <origin
        xyz="0 0 0"
        rpy="0 0 0" />
      <geometry>
        <mesh
          filename="package://fi1-1.STL" />
      </geometry>
    </collision>
  </link>
  <joint
    name="fi1-1joint"
    type="revolute">
    <origin
      xyz="-0.0195 0.025395 0.049809"
      rpy="1.5708 0.02618 1.5708" />
    <parent
      link="hand_base_link" />
    <child
      link="fi1-1" />
    <axis
      xyz="0 0 1" />
    <limit
      lower="-1.047"
      upper="1.047"
      effort="0"
      velocity="0" />
  </joint>
  <link
    name="fi1-2">
    <inertial>
      <origin
        xyz="0.027565 -0.007648 -7.2E-05"
        rpy="0 0 0" />
      <mass
        value="0.043" />
      <inertia
        ixx="3.25E-06"
        ixy="-2.843E-06"
        ixz="-2.9E-08"
        iyy="8.887E-06"
        iyz="3E-09"
        izz="1.0343E-05" />
    </inertial>
    <visual>
      <origin
        xyz="0 0 0"
        rpy="0 0 0" />
      <geometry>
        <mesh
          filename="package://fi1-2.STL" />
      </geometry>
      <material
        name="">
        <color
          rgba="0.65 0.8 0.9 1" />
      </material>
    </visual>
    <collision>
      <origin
        xyz="0 0 0"
        rpy="0 0 0" />
      <geometry>
        <mesh
          filename="package://fi1-2.STL" />
      </geometry>
    </collision>
  </link>
  <joint
    name="fi1-2joint"
    type="revolute">
    <origin
      xyz="0 0 0"
      rpy="1.5708 0 1.5708" />
    <parent
      link="fi1-1" />
    <child
      link="fi1-2" />
    <axis
      xyz="0 0 1" />
    <limit
      lower="0"
      upper="2.09"
      effort="0"
      velocity="0" />
  </joint>
  <link
    name="fi1-3">
    <inertial>
      <origin
        xyz="0.009068 -0.001624 0.001364"
        rpy="0 0 0" />
      <mass
        value="0.015" />
      <inertia
        ixx="1.028E-06"
        ixy="-3.6E-07"
        ixz="-1.86E-07"
        iyy="1.028E-06"
        iyz="6.1E-08"
        izz="1.905E-06" />
    </inertial>
    <visual>
      <origin
        xyz="0 0 0"
        rpy="0 0 0" />
      <geometry>
        <mesh
          filename="package://fi1-3.STL" />
      </geometry>
      <material
        name="">
        <color
          rgba="0.6 0.8 0.9 1" />
      </material>
    </visual>
    <collision>
      <origin
        xyz="0 0 0"
        rpy="0 0 0" />
      <geometry>
        <mesh
          filename="package://fi1-3.STL" />
      </geometry>
    </collision>
  </link>
  <joint
    name="fi1-3joint"
    type="revolute">
    <origin
      xyz="0.048883 -0.018383 0"
      rpy="0 0 0" />
    <parent
      link="fi1-2" />
    <child
      link="fi1-3" />
    <axis
      xyz="0 0 1" />
    <limit
      lower="0"
      upper="1.744"
      effort="0"
      velocity="0" />
  </joint>
  <link
    name="fi1-4">
    <inertial>
      <origin
        xyz="0.006445 -0.003732 -0.000802"
        rpy="0 0 0" />
      <mass
        value="0.005" />
      <inertia
        ixx="2.46E-07"
        ixy="-1.51E-07"
        ixz="1.8E-08"
        iyy="3.86E-07"
        iyz="-8E-09"
        izz="4.83E-07" />
    </inertial>
    <visual>
      <origin
        xyz="0 0 0"
        rpy="0 0 0" />
      <geometry>
        <mesh
          filename="package://fi1-4.STL" />
      </geometry>
      <material
        name="">
        <color
          rgba="0.55 0.8 0.9 1" />
      </material>
    </visual>
    <collision>
      <origin
        xyz="0 0 0"
        rpy="0 0 0" />
      <geometry>
        <mesh
          filename="package://fi1-4.STL" />
      </geometry>
    </collision>
  </link>
  <joint
    name="fi1-4joint"
    type="revolute">
    <origin
      xyz="0.0284 -0.0092477 0"
      rpy="0 0 0" />
    <parent
      link="fi1-3" />
    <child
      link="fi1-4" />
    <axis
      xyz="0 0 1" />
    <limit
      lower="0"
      upper="1.744"
      effort="0"
      velocity="0" />
  </joint>
  <link
    name="fi1-4touch">
    <inertial>
      <origin
        xyz="-0.010782 -5.6649E-06 -2.6126E-06"
        rpy="0 0 0" />
      <mass
        value="3.6105E-23" />
      <inertia
        ixx="1.3674E-27"
        ixy="6.33E-28"
        ixz="3.4104E-32"
        iyy="1.5106E-27"
        iyz="3.1123E-32"
        izz="2.09E-27" />
    </inertial>
    <!--visual>
      <origin
        xyz="0 0 0"
        rpy="0 0 0" />
      <geometry>
        <mesh
          filename="package://fi1-4touch.STL" />
      </geometry>
      <material
        name="">
        <color
          rgba="0.55 0.8 0.9 1" />
      </material>
    </visual>
    <collision>
      <origin
        xyz="0 0 0"
        rpy="0 0 0" />
      <geometry>
        <mesh
          filename="package://fi1-4touch.STL" />
      </geometry>
    </collision-->
  </link>
  <joint
    name="fi1-4touch_joint"
    type="fixed">
    <origin
      xyz="0.019197 -0.0044311 0"
      rpy="0 0 0" />
    <parent
      link="fi1-4" />
    <child
      link="fi1-4touch" />
    <axis
      xyz="0 0 0" />
  </joint>
  <link
    name="fi1-3touch">
    <inertial>
      <origin
        xyz="-0.0087241 -0.0069168 0.00059139"
        rpy="0 0 0" />
      <mass
        value="4.1572E-23" />
      <inertia
        ixx="1.2678E-27"
        ixy="5.7082E-28"
        ixz="2.6371E-29"
        iyy="2.8462E-27"
        iyz="-6.4632E-30"
        izz="3.5231E-27" />
    </inertial>
    <!--visual>
      <origin
        xyz="0 0 0"
        rpy="0 0 0" />
      <geometry>
        <mesh
          filename="package://fi1-3touch.STL" />
      </geometry>
      <material
        name="">
        <color
          rgba="0.6 0.8 0.9 1" />
      </material>
    </visual>
    <collision>
      <origin
        xyz="0 0 0"
        rpy="0 0 0" />
      <geometry>
        <mesh
          filename="package://fi1-3touch.STL" />
      </geometry>
    </collision-->
  </link>
  <joint
    name="fi1-3touch_joint"
    type="fixed">
    <origin
      xyz="0.0210575422960113 0.00463599098917444 0"
      rpy="0 0 0" />
    <parent
      link="fi1-3" />
    <child
      link="fi1-3touch" />
    <axis
      xyz="0 0 0" />
  </joint>
  <link
    name="fi1-2touch">
    <inertial>
      <origin
        xyz="-0.0037034 -0.010757 -2.2232E-05"
        rpy="0 0 0" />
      <mass
        value="1.2329E-22" />
      <inertia
        ixx="7.0351E-27"
        ixy="6.9188E-27"
        ixz="2.067E-30"
        iyy="1.9693E-26"
        iyz="-5.3703E-30"
        izz="2.5283E-26" />
    </inertial>
    <!--visual>
      <origin
        xyz="0 0 0"
        rpy="0 0 0" />
      <geometry>
        <mesh
          filename="package://fi1-2touch.STL" />
      </geometry>
      <material
        name="">
        <color
          rgba="0.65 0.8 0.9 1" />
      </material>
    </visual>
    <collision>
      <origin
        xyz="0 0 0"
        rpy="0 0 0" />
      <geometry>
        <mesh
          filename="package://fi1-2touch.STL" />
      </geometry>
    </collision-->
  </link>
  <joint
    name="fi1-2touch_joint"
    type="fixed">
    <origin
      xyz="0.032801334006575 0.0035035469377151 0"
      rpy="0 0 0" />
    <parent
      link="fi1-2" />
    <child
      link="fi1-2touch" />
    <axis
      xyz="0 0 0" />
  </joint>
  <link
    name="fi2-1">
    <inertial>
      <origin
        xyz="0 0 -0.006816"
        rpy="0 0 0" />
      <mass
        value="0.006" />
      <inertia
        ixx="2.93E-07"
        ixy="0"
        ixz="0"
        iyy="3.19E-07"
        iyz="0"
        izz="5.1E-08" />
    </inertial>
    <visual>
      <origin
        xyz="0 0 0"
        rpy="0 0 0" />
      <geometry>
        <mesh
          filename="package://fi2-1.STL" />
      </geometry>
      <material
        name="">
        <color
          rgba="0.7 0.75 0.9 1" />
      </material>
    </visual>
    <collision>
      <origin
        xyz="0 0 0"
        rpy="0 0 0" />
      <geometry>
        <mesh
          filename="package://fi2-1.STL" />
      </geometry>
    </collision>
  </link>
  <joint
    name="fi2-1joint"
    type="revolute">
    <origin
      xyz="-0.0195 0 0.059698"
      rpy="1.5708 0 1.5708" />
    <parent
      link="hand_base_link" />
    <child
      link="fi2-1" />
    <axis
      xyz="0 0 1" />
    <limit
      lower="-1.047"
      upper="1.047"
      effort="0"
      velocity="0" />
  </joint>
  <link
    name="fi2-2">
    <inertial>
      <origin
        xyz="0.027818 -0.007854 -7.1E-05"
        rpy="0 0 0" />
      <mass
        value="0.044" />
      <inertia
        ixx="3.441E-06"
        ixy="-3.052E-06"
        ixz="-2.8E-08"
        iyy="9.144E-06"
        iyz="2E-09"
        izz="1.0782E-05" />
    </inertial>
    <visual>
      <origin
        xyz="0 0 0"
        rpy="0 0 0" />
      <geometry>
        <mesh
          filename="package://fi2-2.STL" />
      </geometry>
      <material
        name="">
        <color
          rgba="0.7 0.7 0.9 1" />
      </material>
    </visual>
    <collision>
      <origin
        xyz="0 0 0"
        rpy="0 0 0" />
      <geometry>
        <mesh
          filename="package://fi2-2.STL" />
      </geometry>
    </collision>
  </link>
  <joint
    name="fi2-2joint"
    type="revolute">
    <origin
      xyz="0 0 0"
      rpy="1.5708 0 1.5708" />
    <parent
      link="fi2-1" />
    <child
      link="fi2-2" />
    <axis
      xyz="0 0 1" />
    <limit
      lower="0"
      upper="2.09"
      effort="0"
      velocity="0" />
  </joint>
  <link
    name="fi2-3">
    <inertial>
      <origin
        xyz="0.009361 -0.001614 0.001247"
        rpy="0 0 0" />
      <mass
        value="0.016" />
      <inertia
        ixx="1.046E-06"
        ixy="-3.59E-07"
        ixz="-2.02E-07"
        iyy="2.231E-06"
        iyz="6E-08"
        izz="1.96E-06" />
    </inertial>
    <visual>
      <origin
        xyz="0 0 0"
        rpy="0 0 0" />
      <geometry>
        <mesh
          filename="package://fi2-3.STL" />
      </geometry>
      <material
        name="">
        <color
          rgba="0.7 0.65 0.9 1" />
      </material>
    </visual>
    <collision>
      <origin
        xyz="0 0 0"
        rpy="0 0 0" />
      <geometry>
        <mesh
          filename="package://fi2-3.STL" />
      </geometry>
    </collision>
  </link>
  <joint
    name="fi2-3joint"
    type="revolute">
    <origin
      xyz="0.048883 -0.018383 0"
      rpy="0 0 0" />
    <parent
      link="fi2-2" />
    <child
      link="fi2-3" />
    <axis
      xyz="0 0 1" />
    <limit
      lower="0"
      upper="1.744"
      effort="0"
      velocity="0" />
  </joint>
  <link
    name="fi2-4">
    <inertial>
      <origin
        xyz="0.006445 -0.003732 -0.000802"
        rpy="0 0 0" />
      <mass
        value="0.005" />
      <inertia
        ixx="2.46E-07"
        ixy="-1.51E-07"
        ixz="1.8E-08"
        iyy="3.86E-07"
        iyz="-8E-09"
        izz="4.83E-07" />
    </inertial>
    <visual>
      <origin
        xyz="0 0 0"
        rpy="0 0 0" />
      <geometry>
        <mesh
          filename="package://fi2-4.STL" />
      </geometry>
      <material
        name="">
        <color
          rgba="0.7 0.6 0.9 1" />
      </material>
    </visual>
    <collision>
      <origin
        xyz="0 0 0"
        rpy="0 0 0" />
      <geometry>
        <mesh
          filename="package://fi2-4.STL" />
      </geometry>
    </collision>
  </link>
  <joint
    name="fi2-4joint"
    type="revolute">
    <origin
      xyz="0.0284 -0.0092477 0"
      rpy="0 0 0" />
    <parent
      link="fi2-3" />
    <child
      link="fi2-4" />
    <axis
      xyz="0 0 1" />
    <limit
      lower="0"
      upper="1.744"
      effort="0"
      velocity="0" />
  </joint>
  <link
    name="fi2-4touch">
    <inertial>
      <origin
        xyz="-0.010782 -5.6645E-06 -2.6184E-06"
        rpy="0 0 0" />
      <mass
        value="3.6105E-23" />
      <inertia
        ixx="1.3674E-27"
        ixy="6.33E-28"
        ixz="3.3962E-32"
        iyy="1.5106E-27"
        iyz="3.0154E-32"
        izz="2.09E-27" />
    </inertial>
    <!--visual>
      <origin
        xyz="0 0 0"
        rpy="0 0 0" />
      <geometry>
        <mesh
          filename="package://fi2-4touch.STL" />
      </geometry>
      <material
        name="">
        <color
          rgba="0.7 0.6 0.9 1" />
      </material>
    </visual>
    <collision>
      <origin
        xyz="0 0 0"
        rpy="0 0 0" />
      <geometry>
        <mesh
          filename="package://fi2-4touch.STL" />
      </geometry>
    </collision!-->
  </link>
  <joint
    name="fi2-4touch_joint"
    type="fixed">
    <origin
      xyz="0.019197 -0.0044311 0"
      rpy="0 0 0" />
    <parent
      link="fi2-4" />
    <child
      link="fi2-4touch" />
    <axis
      xyz="0 0 0" />
  </joint>
  <link
    name="fi2-3touch">
    <inertial>
      <origin
        xyz="-0.0087748 -0.0071693 0.00054933"
        rpy="0 0 0" />
      <mass
        value="4.2212E-23" />
      <inertia
        ixx="1.277E-27"
        ixy="5.7082E-28"
        ixz="2.6371E-29"
        iyy="2.8554E-27"
        iyz="-6.4632E-30"
        izz="3.5233E-27" />
    </inertial>
    <!--visual>
      <origin
        xyz="0 0 0"
        rpy="0 0 0" />
      <geometry>
        <mesh
          filename="package://fi2-3touch.STL" />
      </geometry>
      <material
        name="">
        <color
          rgba="0.7 0.65 0.9 1" />
      </material>
    </visual>
    <collision>
      <origin
        xyz="0 0 0"
        rpy="0 0 0" />
      <geometry>
        <mesh
          filename="package://fi2-3touch.STL" />
      </geometry>
    </collision-->
  </link>
  <joint
    name="fi2-3touch_joint"
    type="fixed">
    <origin
      xyz="0.0211938899395907 0.00490321621270379 0"
      rpy="0 0 0" />
    <parent
      link="fi2-3" />
    <child
      link="fi2-3touch" />
    <axis
      xyz="0 0 0" />
  </joint>
  <link
    name="fi2-2touch">
    <inertial>
      <origin
        xyz="-0.0036013 -0.010849 -2.2102E-05"
        rpy="0 0 0" />
      <mass
        value="1.2402E-22" />
      <inertia
        ixx="7.0368E-27"
        ixy="6.9188E-27"
        ixz="2.0671E-30"
        iyy="1.9694E-26"
        iyz="-5.3702E-30"
        izz="2.5285E-26" />
    </inertial>
    <!--visual>
      <origin
        xyz="0 0 0"
        rpy="0 0 0" />
      <geometry>
        <mesh
          filename="package://fi2-2touch.STL" />
      </geometry>
      <material
        name="">
        <color
          rgba="0.7 0.7 0.9 1" />
      </material>
    </visual>
    <collision>
      <origin
        xyz="0 0 0"
        rpy="0 0 0" />
      <geometry>
        <mesh
          filename="package://fi2-2touch.STL" />
      </geometry>
    </collision-->
  </link>
  <joint
    name="fi2-2touch_joint"
    type="fixed">
    <origin
      xyz="0.0328013340065718 0.0035035469377443 0"
      rpy="0 0 0" />
    <parent
      link="fi2-2" />
    <child
      link="fi2-2touch" />
    <axis
      xyz="0 0 0" />
  </joint>
  <link
    name="fi3-1">
    <inertial>
      <origin
        xyz="0 -0.000671 -0.01356"
        rpy="0 0 0" />
      <mass
        value="0.008" />
      <inertia
        ixx="7.89E-07"
        ixy="0"
        ixz="0"
        iyy="7.81E-07"
        iyz="3.9E-08"
        izz="1.21E-07" />
    </inertial>
    <visual>
      <origin
        xyz="0 0 0"
        rpy="0 0 0" />
      <geometry>
        <mesh
          filename="package://fi3-1.STL" />
      </geometry>
      <material
        name="">
        <color
          rgba="0.7 0.8 0.85 1" />
      </material>
    </visual>
    <collision>
      <origin
        xyz="0 0 0"
        rpy="0 0 0" />
      <geometry>
        <mesh
          filename="package://fi3-1.STL" />
      </geometry>
    </collision>
  </link>
  <joint
    name="fi3-1joint"
    type="revolute">
    <origin
      xyz="-0.0185 -0.0198 0.053951"
      rpy="1.5708 0 1.5708" />
    <parent
      link="hand_base_link" />
    <child
      link="fi3-1" />
    <axis
      xyz="0 0 1" />
    <limit
      lower="-1.047"
      upper="1.047"
      effort="0"
      velocity="0" />
  </joint>
  <link
    name="fi3-2">
    <inertial>
      <origin
        xyz="0.025872 0.003016 -0.000107"
        rpy="0 0 0" />
      <mass
        value="0.013" />
      <inertia
        ixx="4.8E-07"
        ixy="-1.58E-07"
        ixz="-1E-09"
        iyy="2.515E-06"
        iyz="-1E-09"
        izz="2.646E-06" />
    </inertial>
    <visual>
      <origin
        xyz="0 0 0"
        rpy="0 0 0" />
      <geometry>
        <mesh
          filename="package://fi3-2.STL" />
      </geometry>
      <material
        name="">
        <color
          rgba="0.7 0.8 0.8 1" />
      </material>
    </visual>
    <collision>
      <origin
        xyz="0 0 0"
        rpy="0 0 0" />
      <geometry>
        <mesh
          filename="package://fi3-2.STL" />
      </geometry>
    </collision>
  </link>
  <joint
    name="fi3-2joint"
    type="revolute">
    <origin
      xyz="0 0 0"
      rpy="1.5708 0 1.5708" />
    <parent
      link="fi3-1" />
    <child
      link="fi3-2" />
    <axis
      xyz="0 0 1" />
    <limit
      lower="0"
      upper="1.744"
      effort="0"
      velocity="0" />
  </joint>
  <link
    name="fi3-3">
    <inertial>
      <origin
        xyz="0.010272 -0.000925 -9E-08"
        rpy="0 0 0" />
      <mass
        value="0.007" />
      <inertia
        ixx="2.85E-07"
        ixy="-7.2E-08"
        ixz="-2E-09"
        iyy="7.05E-07"
        iyz="0"
        izz="7.15E-07" />
    </inertial>
    <visual>
      <origin
        xyz="0 0 0"
        rpy="0 0 0" />
      <geometry>
        <mesh
          filename="package://fi3-3.STL" />
      </geometry>
      <material
        name="">
        <color
          rgba="0.7 0.8 0.75 1" />
      </material>
    </visual>
    <collision>
      <origin
        xyz="0 0 0"
        rpy="0 0 0" />
      <geometry>
        <mesh
          filename="package://fi3-3.STL" />
      </geometry>
    </collision>
  </link>
  <joint
    name="fi3-3joint"
    type="revolute">
    <origin
      xyz="0.044995 0.00066781 0"
      rpy="0 0 0" />
    <parent
      link="fi3-2" />
    <child
      link="fi3-3" />
    <axis
      xyz="0 0 1" />
    <limit
      lower="0"
      upper="1.744"
      effort="0"
      velocity="0" />
  </joint>
  <link
    name="fi3-4">
    <inertial>
      <origin
        xyz="0.008412 -0.002732 -1E-05"
        rpy="0 0 0" />
      <mass
        value="0.005" />
      <inertia
        ixx="1.41E-07"
        ixy="-6.8E-08"
        ixz="0"
        iyy="2.86E-07"
        iyz="0"
        izz="3.38E-07" />
    </inertial>
    <visual>
      <origin
        xyz="0 0 0"
        rpy="0 0 0" />
      <geometry>
        <mesh
          filename="package://fi3-4.STL" />
      </geometry>
      <material
        name="">
        <color
          rgba="0.7 0.8 0.7 1" />
      </material>
    </visual>
    <collision>
      <origin
        xyz="0 0 0"
        rpy="0 0 0" />
      <geometry>
        <mesh
          filename="package://fi3-4.STL" />
      </geometry>
    </collision>
  </link>
  <joint
    name="fi3-4joint"
    type="revolute">
    <origin
      xyz="0.024601 -0.0044465 0"
      rpy="0 0 0" />
    <parent
      link="fi3-3" />
    <child
      link="fi3-4" />
    <axis
      xyz="0 0 1" />
    <limit
      lower="0"
      upper="1.744"
      effort="0"
      velocity="0" />
  </joint>
  <link
    name="fi3-4touch">
    <inertial>
      <origin
        xyz="-0.0056431 -0.0053994 -9.5986E-07"
        rpy="0 0 0" />
      <mass
        value="2.688E-23" />
      <inertia
        ixx="7.66E-28"
        ixy="2.9606E-28"
        ixz="6.9724E-32"
        iyy="9.7921E-28"
        iyz="2.9089E-32"
        izz="1.2301E-27" />
    </inertial>
    <!--visual>
      <origin
        xyz="0 0 0"
        rpy="0 0 0" />
      <geometry>
        <mesh
          filename="package://fi3-4touch.STL" />
      </geometry>
      <material
        name="">
        <color
          rgba="0.7 0.8 0.7 1" />
      </material>
    </visual>
    <collision>
      <origin
        xyz="0 0 0"
        rpy="0 0 0" />
      <geometry>
        <mesh
          filename="package://fi3-4touch.STL" />
      </geometry>
    </collision-->
  </link>
  <joint
    name="fi3-4touch_joint"
    type="fixed">
    <origin
      xyz="0.016705 0.0025009 0"
      rpy="0 0 0" />
    <parent
      link="fi3-4" />
    <child
      link="fi3-4touch" />
    <axis
      xyz="0 0 0" />
  </joint>
  <link
    name="fi3-3touch">
    <inertial>
      <origin
        xyz="-0.0054673 -0.007841 9.8595E-07"
        rpy="0 0 0" />
      <mass
        value="2.5751E-23" />
      <inertia
        ixx="5.0998E-28"
        ixy="2.5108E-28"
        ixz="-9.6659E-31"
        iyy="2.0108E-27"
        iyz="5.2228E-31"
        izz="2.3958E-27" />
    </inertial>
    <!--visual>
      <origin
        xyz="0 0 0"
        rpy="0 0 0" />
      <geometry>
        <mesh
          filename="package://fi3-3touch.STL" />
      </geometry>
      <material
        name="">
        <color
          rgba="0.7 0.8 0.75 1" />
      </material>
    </visual>
    <collision>
      <origin
        xyz="0 0 0"
        rpy="0 0 0" />
      <geometry>
        <mesh
          filename="package://fi3-3touch.STL" />
      </geometry>
    </collision-->
  </link>
  <joint
    name="fi3-3touch_joint"
    type="fixed">
    <origin
      xyz="0.015801 0.0073061 0"
      rpy="0 0 0" />
    <parent
      link="fi3-3" />
    <child
      link="fi3-3touch" />
    <axis
      xyz="0 0 0" />
  </joint>
  <link
    name="fi3-2touch">
    <inertial>
      <origin
        xyz="-0.00095354 -0.0083816 2.2003E-06"
        rpy="0 0 0" />
      <mass
        value="4.5951E-23" />
      <inertia
        ixx="1.0301E-27"
        ixy="3.7497E-28"
        ixz="1.9225E-30"
        iyy="7.5194E-27"
        iyz="-2.143E-30"
        izz="8.2684E-27" />
    </inertial>
    <!--visual>
      <origin
        xyz="0 0 0"
        rpy="0 0 0" />
      <geometry>
        <mesh
          filename="package://fi3-2touch.STL" />
      </geometry>
      <material
        name="">
        <color
          rgba="0.7 0.8 0.8 1" />
      </material>
    </visual>
    <collision>
      <origin
        xyz="0 0 0"
        rpy="0 0 0" />
      <geometry>
        <mesh
          filename="package://fi3-2touch.STL" />
      </geometry>
    </collision-->
  </link>
  <joint
    name="fi3-2touch_joint"
    type="fixed">
    <origin
      xyz="0.026367 0.011864 0"
      rpy="0 0 0" />
    <parent
      link="fi3-2" />
    <child
      link="fi3-2touch" />
    <axis
      xyz="0 0 0" />
  </joint>
  <link
    name="fi4-1">
    <inertial>
      <origin
        xyz="0 -0.000671 -0.01356"
        rpy="0 0 0" />
      <mass
        value="0.008" />
      <inertia
        ixx="7.89E-07"
        ixy="0"
        ixz="0"
        iyy="7.81E-07"
        iyz="3.9E-08"
        izz="1.21E-07" />
    </inertial>
    <visual>
      <origin
        xyz="0 0 0"
        rpy="0 0 0" />
      <geometry>
        <mesh
          filename="package://fi4-1.STL" />
      </geometry>
      <material
        name="">
        <color
          rgba="0.65 0.75 0.9 1" />
      </material>
    </visual>
    <collision>
      <origin
        xyz="0 0 0"
        rpy="0 0 0" />
      <geometry>
        <mesh
          filename="package://fi4-1.STL" />
      </geometry>
    </collision>
  </link>
  <joint
    name="fi4-1joint"
    type="revolute">
    <origin
      xyz="-0.0185 -0.036717 0.038536"
      rpy="1.5708 -0.034907 1.5708" />
    <parent
      link="hand_base_link" />
    <child
      link="fi4-1" />
    <axis
      xyz="0 0 1" />
    <limit
      lower="-1.047"
      upper="1.047"
      effort="0"
      velocity="0" />
  </joint>
  <link
    name="fi4-2">
    <inertial>
      <origin
        xyz="0.021238 0.003537 2E-06"
        rpy="0 0 0" />
      <mass
        value="0.01" />
      <inertia
        ixx="3.4E-07"
        ixy="0"
        ixz="3.9E-08"
        iyy="1.374E-06"
        iyz="0"
        izz="1.453E-06" />
    </inertial>
    <visual>
      <origin
        xyz="0 0 0"
        rpy="0 0 0" />
      <geometry>
        <mesh
          filename="package://fi4-2.STL" />
      </geometry>
      <material
        name="">
        <color
          rgba="0.6 0.7 0.9 1" />
      </material>
    </visual>
    <collision>
      <origin
        xyz="0 0 0"
        rpy="0 0 0" />
      <geometry>
        <mesh
          filename="package://fi4-2.STL" />
      </geometry>
    </collision>
  </link>
  <joint
    name="fi4-2joint"
    type="revolute">
    <origin
      xyz="0 0 0"
      rpy="1.5708 0 1.5708" />
    <parent
      link="fi4-1" />
    <child
      link="fi4-2" />
    <axis
      xyz="0 0 1" />
    <limit
      lower="0"
      upper="1.7"
      effort="0"
      velocity="0" />
  </joint>
  <link
    name="fi4-3">
    <inertial>
      <origin
        xyz="0.010255 -0.000855 -8.9E-05"
        rpy="0 0 0" />
      <mass
        value="0.007" />
      <inertia
        ixx="2.89E-07"
        ixy="-7E-08"
        ixz="-2E-09"
        iyy="7.18E-07"
        iyz="0"
        izz="7.27E-07" />
    </inertial>
    <visual>
      <origin
        xyz="0 0 0"
        rpy="0 0 0" />
      <geometry>
        <mesh
          filename="package://fi4-3.STL" />
      </geometry>
      <material
        name="">
        <color
          rgba="0.55 0.65 0.9 1" />
      </material>
    </visual>
    <collision>
      <origin
        xyz="0 0 0"
        rpy="0 0 0" />
      <geometry>
        <mesh
          filename="package://fi4-3.STL" />
      </geometry>
    </collision>
  </link>
  <joint
    name="fi4-3joint"
    type="revolute">
    <origin
      xyz="0.035975 0.001338 0"
      rpy="0 0 0" />
    <parent
      link="fi4-2" />
    <child
      link="fi4-3" />
    <axis
      xyz="0 0 1" />
    <limit
      lower="0"
      upper="1.744"
      effort="0"
      velocity="0" />
  </joint>
  <link
    name="fi4-4">
    <inertial>
      <origin
        xyz="0.008341 -0.002627 -1E-05"
        rpy="0 0 0" />
      <mass
        value="0.005" />
      <inertia
        ixx="1.4E-07"
        ixy="-6.8E-08"
        ixz="0"
        iyy="2.91E-07"
        iyz="0"
        izz="3.42E-07" />
    </inertial>
    <visual>
      <origin
        xyz="0 0 0"
        rpy="0 0 0" />
      <geometry>
        <mesh
          filename="package://fi4-4.STL" />
      </geometry>
      <material
        name="">
        <color
          rgba="0.5 0.6 0.9 1" />
      </material>
    </visual>
    <collision>
      <origin
        xyz="0 0 0"
        rpy="0 0 0" />
      <geometry>
        <mesh
          filename="package://fi4-4.STL" />
      </geometry>
    </collision>
  </link>
  <joint
    name="fi4-4joint"
    type="revolute">
    <origin
      xyz="0.024621 -0.004339 0"
      rpy="0 0 0" />
    <parent
      link="fi4-3" />
    <child
      link="fi4-4" />
    <axis
      xyz="0 0 1" />
    <limit
      lower="0"
      upper="1.744"
      effort="0"
      velocity="0" />
  </joint>
  <link
    name="fi4-4touch">
    <inertial>
      <origin
        xyz="-0.0056699 -0.0054353 -1.0043E-06"
        rpy="0 0 0" />
      <mass
        value="2.7068E-23" />
      <inertia
        ixx="7.6122E-28"
        ixy="2.956E-28"
        ixz="6.4904E-32"
        iyy="9.8945E-28"
        iyz="4.2389E-32"
        izz="1.2355E-27" />
    </inertial>
    <!--visual>
      <origin
        xyz="0 0 0"
        rpy="0 0 0" />
      <geometry>
        <mesh
          filename="package://fi4-4touch.STL" />
      </geometry>
      <material
        name="">
        <color
          rgba="0.5 0.6 0.9 1" />
      </material>
    </visual>
    <collision>
      <origin
        xyz="0 0 0"
        rpy="0 0 0" />
      <geometry>
        <mesh
          filename="package://fi4-4touch.STL" />
      </geometry>
    </collision-->
  </link>
  <joint
    name="fi4-4touch_joint"
    type="fixed">
    <origin
      xyz="0.016681 0.0026535 0"
      rpy="0 0 0" />
    <parent
      link="fi4-4" />
    <child
      link="fi4-4touch" />
    <axis
      xyz="0 0 0" />
  </joint>
  <link
    name="fi4-3touch">
    <inertial>
      <origin
        xyz="-0.0049808 -0.0079444 1.1255E-06"
        rpy="0 0 0" />
      <mass
        value="2.604E-23" />
      <inertia
        ixx="5.1315E-28"
        ixy="2.4701E-28"
        ixz="-9.6418E-31"
        iyy="2.0418E-27"
        iyz="4.8658E-32"
        izz="2.429E-27" />
    </inertial>
    <!--visual>
      <origin
        xyz="0 0 0"
        rpy="0 0 0" />
      <geometry>
        <mesh
          filename="package://fi4-3touch.STL" />
      </geometry>
      <material
        name="">
        <color
          rgba="0.55 0.65 0.9 1" />
      </material>
    </visual>
    <collision>
      <origin
        xyz="0 0 0"
        rpy="0 0 0" />
      <geometry>
        <mesh
          filename="package://fi4-3touch.STL" />
      </geometry>
    </collision-->
  </link>
  <joint
    name="fi4-3touch_joint"
    type="fixed">
    <origin
      xyz="0.015277 0.0074618 0"
      rpy="0 0 0" />
    <parent
      link="fi4-3" />
    <child
      link="fi4-3touch" />
    <axis
      xyz="0 0 0" />
  </joint>
  <link
    name="fi4-2touch">
    <inertial>
      <origin
        xyz="-0.001065 -0.0086285 2.2338E-06"
        rpy="0 0 0" />
      <mass
        value="3.3846E-23" />
      <inertia
        ixx="7.345E-28"
        ixy="8.7239E-29"
        ixz="3.1948E-30"
        iyy="4.0435E-27"
        iyz="-2.1647E-30"
        izz="4.5853E-27" />
    </inertial>
    <!--visual>
      <origin
        xyz="0 0 0"
        rpy="0 0 0" />
      <geometry>
        <mesh
          filename="package://fi4-2touch.STL" />
      </geometry>
      <material
        name="">
        <color
          rgba="0.6 0.7 0.9 1" />
      </material>
    </visual>
    <collision>
      <origin
        xyz="0 0 0"
        rpy="0 0 0" />
      <geometry>
        <mesh
          filename="package://fi4-2touch.STL" />
      </geometry>
    </collision-->
  </link>
  <joint
    name="fi4-2touch_joint"
    type="fixed">
    <origin
      xyz="0.022303 0.012165 0"
      rpy="0 0 0" />
    <parent
      link="fi4-2" />
    <child
      link="fi4-2touch" />
    <axis
      xyz="0 0 0" />
  </joint>
  <link
    name="fi5-1">
    <inertial>
      <origin
        xyz="0.004928 0.023413 0.032334"
        rpy="0 0 0" />
      <mass
        value="0.207" />
      <inertia
        ixx="0.00011189"
        ixy="-2.41E-07"
        ixz="4.239E-06"
        iyy="6.5904E-05"
        iyz="3.8219E-05"
        izz="6.8534E-05" />
    </inertial>
    <visual>
      <origin
        xyz="0 0 0"
        rpy="0 0 0" />
      <geometry>
        <mesh
          filename="package://fi5-1.STL" />
      </geometry>
      <material
        name="">
        <color
          rgba="0.7 0.7 0.8 1" />
      </material>
    </visual>
    <collision>
      <origin
        xyz="0 0 0"
        rpy="0 0 0" />
      <geometry>
        <mesh
          filename="package://fi5-1.STL" />
      </geometry>
    </collision>
  </link>
  <joint
    name="fi5-1joint"
    type="revolute">
    <origin
      xyz="0.0024692 0.006194 -0.060602"
      rpy="0 0 0" />
    <parent
      link="hand_base_link" />
    <child
      link="fi5-1" />
    <axis
      xyz="0 0 -1" />
    <limit
      lower="0"
      upper="2.09"
      effort="0"
      velocity="0" />
  </joint>
  <link
    name="fi5-2">
    <inertial>
      <origin
        xyz="0 -0.000133 -0.00788"
        rpy="0 0 0" />
      <mass
        value="0.006" />
      <inertia
        ixx="3.6E-07"
        ixy="0"
        ixz="0"
        iyy="3.88E-07"
        iyz="-2E-09"
        izz="5.1E-08" />
    </inertial>
    <visual>
      <origin
        xyz="0 0 0"
        rpy="0 0 0" />
      <geometry>
        <mesh
          filename="package://fi5-2.STL" />
      </geometry>
      <material
        name="">
        <color
          rgba="0.7 0.68 0.78 1" />
      </material>
    </visual>
    <collision>
      <origin
        xyz="0 0 0"
        rpy="0 0 0" />
      <geometry>
        <mesh
          filename="package://fi5-2.STL" />
      </geometry>
    </collision>
  </link>
  <joint
    name="fi5-2joint"
    type="revolute">
    <origin
      xyz="0.0070384 0.052727 0.06422"
      rpy="0.72891 0.2651 0.22982" />
    <parent
      link="fi5-1" />
    <child
      link="fi5-2" />
    <axis
      xyz="0 0 1" />
    <limit
      lower="-1.047"
      upper="1.047"
      effort="0"
      velocity="0" />
  </joint>
  <link
    name="fi5-3">
    <inertial>
      <origin
        xyz="0.022364 0.004293 -0.000109"
        rpy="0 0 0" />
      <mass
        value="0.012" />
      <inertia
        ixx="5.99E-07"
        ixy="6E-09"
        ixz="-1E-09"
        iyy="1.818E-06"
        iyz="-3E-09"
        izz="1.779E-06" />
    </inertial>
    <visual>
      <origin
        xyz="0 0 0"
        rpy="0 0 0" />
      <geometry>
        <mesh
          filename="package://fi5-3.STL" />
      </geometry>
      <material
        name="">
        <color
          rgba="0.7 0.65 0.75 1" />
      </material>
    </visual>
    <collision>
      <origin
        xyz="0 0 0"
        rpy="0 0 0" />
      <geometry>
        <mesh
          filename="package://fi5-3.STL" />
      </geometry>
    </collision>
  </link>
  <joint
    name="fi5-3joint"
    type="revolute">
    <origin
      xyz="0 0 0"
      rpy="1.5708 0 1.5708" />
    <parent
      link="fi5-2" />
    <child
      link="fi5-3" />
    <axis
      xyz="0 0 1" />
    <limit
      lower="0"
      upper="1.744"
      effort="0"
      velocity="0" />
  </joint>
  <link
    name="fi5-4">
    <inertial>
      <origin
        xyz="0.010875 -0.001252 -6.7E-05"
        rpy="0 0 0" />
      <mass
        value="0.009" />
      <inertia
        ixx="5.22E-07"
        ixy="-1.17E-07"
        ixz="1E-09"
        iyy="1.004E-06"
        iyz="-1E-09"
        izz="8.11E-07" />
    </inertial>
    <visual>
      <origin
        xyz="0 0 0"
        rpy="0 0 0" />
      <geometry>
        <mesh
          filename="package://fi5-4.STL" />
      </geometry>
      <material
        name="">
        <color
          rgba="0.7 0.6 0.7 1" />
      </material>
    </visual>
    <collision>
      <origin
        xyz="0 0 0"
        rpy="0 0 0" />
      <geometry>
        <mesh
          filename="package://fi5-4.STL" />
      </geometry>
    </collision>
  </link>
  <joint
    name="fi5-4joint"
    type="revolute">
    <origin
      xyz="0.03577 0.0040652 0"
      rpy="0 0 0" />
    <parent
      link="fi5-3" />
    <child
      link="fi5-4" />
    <axis
      xyz="0 0 1" />
    <limit
      lower="0"
      upper="1.744"
      effort="0"
      velocity="0" />
  </joint>
  <link
    name="fi5-4touch">
    <inertial>
      <origin
        xyz="-0.0073557 -0.0050501 -9.0692E-06"
        rpy="0 0 0" />
      <mass
        value="4.7764E-23" />
      <inertia
        ixx="1.9481E-27"
        ixy="5.0128E-28"
        ixz="-2.6646E-31"
        iyy="3.0598E-27"
        iyz="-1.2989E-31"
        izz="2.7048E-27" />
    </inertial>
    <!--visual>
      <origin
        xyz="0 0 0"
        rpy="0 0 0" />
      <geometry>
        <mesh
          filename="package://fi5-4touch.STL" />
      </geometry>
      <material
        name="">
        <color
          rgba="0.7 0.6 0.7 1" />
      </material>
    </visual>
    <collision>
      <origin
        xyz="0 0 0"
        rpy="0 0 0" />
      <geometry>
        <mesh
          filename="package://fi5-4touch.STL" />
      </geometry>
    </collision-->
  </link>
  <joint
    name="fi5-4touch_joint"
    type="fixed">
    <origin
      xyz="0.0209207862572912 0.00375303486703484 0"
      rpy="0 0 0" />
    <parent
      link="fi5-4" />
    <child
      link="fi5-4touch" />
    <axis
      xyz="0 0 0" />
  </joint>
  <link
    name="fi5-3touch">
    <inertial>
      <origin
        xyz="0.00047159 -0.0092471 -8.7156E-06"
        rpy="0 0 0" />
      <mass
        value="4.4634E-23" />
      <inertia
        ixx="1.1112E-27"
        ixy="-9.9034E-29"
        ixz="-2.4496E-30"
        iyy="5.2738E-27"
        iyz="-1.3875E-30"
        izz="5.8295E-27" />
    </inertial>
    <!--visual>
      <origin
        xyz="0 0 0"
        rpy="0 0 0" />
      <geometry>
        <mesh
          filename="package://fi5-3touch.STL" />
      </geometry>
      <material
        name="">
        <color
          rgba="0.7 0.65 0.75 1" />
      </material>
    </visual>
    <collision>
      <origin
        xyz="0 0 0"
        rpy="0 0 0" />
      <geometry>
        <mesh
          filename="package://fi5-3touch.STL" />
      </geometry>
    </collision-->
  </link>
  <joint
    name="fi5-3touch_joint"
    type="fixed">
    <origin
      xyz="0.021472 0.014076 0"
      rpy="0 0 0" />
    <parent
      link="fi5-3" />
    <child
      link="fi5-3touch" />
    <axis
      xyz="0 0 0" />
  </joint>
  <link
    name="fi5-1touch">
    <inertial>
      <origin
        xyz="-0.0060893 -0.024787 -0.0006366"
        rpy="0 0 0" />
      <mass
        value="3.4907E-22" />
      <inertia
        ixx="2.5961E-26"
        ixy="2.0038E-27"
        ixz="5.8798E-29"
        iyy="6.4596E-26"
        iyz="-3.4152E-28"
        izz="6.7029E-26" />
    </inertial>
    <!--visual>
      <origin
        xyz="0 0 0"
        rpy="0 0 0" />
      <geometry>
        <mesh
          filename="package://fi5-1touch.STL" />
      </geometry>
      <material
        name="">
        <color
          rgba="0.7 0.75 0.85 1" />
      </material>
    </visual>
    <collision>
      <origin
        xyz="0 0 0"
        rpy="0 0 0" />
      <geometry>
        <mesh
          filename="package://fi5-1touch.STL" />
      </geometry>
    </collision-->
  </link>
  <joint
    name="fi5-1touch_joint"
    type="fixed">
    <origin
      xyz="0.013916 0.014758 0.054735"
      rpy="1.9199 -0.69813 1.5708" />
    <parent
      link="fi5-1" />
    <child
      link="fi5-1touch" />
    <axis
      xyz="0 0 0" />
  </joint>
  <link
    name="wrist">
    <inertial>
      <origin
        xyz="0.00025407 -0.0082375 0.067327"
        rpy="0 0 0" />
      <mass
        value="2.1833E-21" />
      <inertia
        ixx="9.7165E-25"
        ixy="-3.272E-26"
        ixz="-2.9853E-27"
        iyy="7.1036E-25"
        iyz="-6.2282E-26"
        izz="6.5105E-25" />
    </inertial>
    <!--visual>
      <origin
        xyz="0 0 0"
        rpy="0 0 0" />
      <geometry>
        <mesh
          filename="package://wrist.STL" />
      </geometry>
      <material
        name="">
        <color
          rgba="0.79216 0.81961 0.93333 1" />
      </material>
    </visual>
    <collision>
      <origin
        xyz="0 0 0"
        rpy="0 0 0" />
      <geometry>
        <mesh
          filename="package://wrist.STL" />
      </geometry>
    </collision-->
  </link>
  <joint
    name="wrist_joint"
    type="fixed">
    <origin
      xyz="-0.023273 0.0020397 -0.083602"
      rpy="0 0 0" />
    <parent
      link="hand_base_link" />
    <child
      link="wrist" />
    <axis
      xyz="0 0 0" />
  </joint>
</robot>
